<?xml version="1.0" ?>

<robot name="learnrobotcis" xmlns:xacro="http://ros.org/wiki/xacro">
  <link name="base_link"></link>

  <link name="chassis">
    <visual>
      <origin rpy="0 0 0" xyz="0 0 0" />
      <geometry>
        <mesh filename="file:///home/tecchio/code/catkin_learnbotics/src/learnrobotics/model/stl/modified/complete_robot.stl" />
      </geometry>
      <material name="abs_black">
        <color rgba="0 0 0 1" />
      </material>
    </visual>

    <collision>
      <origin rpy="0 0 0" xyz="0 0 0" />
      <geometry>
        <mesh filename="file:///home/tecchio/code/catkin_learnbotics/src/learnrobotics/model/stl/modified/complete_robot.stl" />
      </geometry>
    </collision>

    <inertial>
      <origin rpy="0 0 0" xyz="0 0 0" />
      <mass value="0.32697605" />
      <inertia ixx="6.63318913e-04" ixy="0" ixz="5.13108151e-05" iyy="1.02936619e-03" iyz="8.02098638e-07" izz="1.20173687e-03" />
    </inertial>
  </link>

  <joint name="chassis_to_base_link" type="fixed">
    <parent link="base_link" />
    <child link="chassis" />
    <origin rpy="0 0 0" xyz="0 0 0" />
  </joint>

  <gazebo reference="chassis">
    <material>Gazebo/Black</material>
  </gazebo>

  <link name="wheel_red">
    <visual>
      <origin rpy="0 0 0" xyz="0 0 0" />
      <geometry>
        <mesh filename="file:///home/tecchio/code/catkin_learnbotics/src/learnrobotics/model/stl/modified/RodaNoCentro.stl" />
      </geometry>
      <material name="abs_red">
        <color rgba="1 0 0 1" />
      </material>
    </visual>

    <collision>
      <origin rpy="0 0 0" xyz="0 0 0" />
      <geometry>
        <mesh filename="file:///home/tecchio/code/catkin_learnbotics/src/learnrobotics/model/stl/modified/RodaNoCentro.stl" />
      </geometry>
    </collision>

    <inertial>
      <origin rpy="0 0 0" xyz="0 0 0" />
      <mass value="0.02705420" />
      <inertia ixx="1.09514547e-05" ixy="3.12490491e-11" ixz="0" iyy="2.13765927e-05" iyz="0" izz="1.09513089e-05" />
    </inertial>
  </link>

  <joint name="chassis_to_wheel_red" type="continuous">
    <parent link="chassis" />
    <child link="wheel_red" />
    <origin rpy="0 0 0" xyz="-0.05762664 -0.06151239 -0.03470413" />
    <axis xyz="0 1 0" />
  </joint>

  <gazebo reference="wheel_red">
    <material>Gazebo/Red</material>
  </gazebo>

  <link name="wheel_blue">
    <visual>
      <origin rpy="0 0 0" xyz="0 0 0" />
      <geometry>
        <mesh filename="file:///home/tecchio/code/catkin_learnbotics/src/learnrobotics/model/stl/modified/RodaNoCentroEspelhada.stl" />
      </geometry>
      <material name="abs_blue">
        <color rgba="0 0 1 1" />
      </material>
    </visual>

    <collision>
      <origin rpy="0 0 0" xyz="0 0 0" />
      <geometry>
        <mesh filename="file:///home/tecchio/code/catkin_learnbotics/src/learnrobotics/model/stl/modified/RodaNoCentroEspelhada.stl" />
      </geometry>
    </collision>

    <inertial>
      <origin rpy="0 0 0" xyz="0 0 0" />
      <mass value="0.02705420" />
      <inertia ixx="1.09514547e-05" ixy="3.12490491e-11" ixz="0" iyy="2.13765927e-05" iyz="0" izz="1.09513089e-05" />
    </inertial>
  </link>

  <joint name="chassis_to_wheel_blue" type="continuous">
    <parent link="chassis" />
    <child link="wheel_blue" />
    <origin rpy="0 0 0" xyz="-0.05762664 0.06151239 -0.03470413" />
    <axis xyz="0 1 0" />
  </joint>

  <gazebo reference="wheel_blue">
    <material>Gazebo/Blue</material>
  </gazebo>

  <link name="sphere">
    <visual>
      <origin rpy="0 0 0" xyz="0 0 0" />
      <geometry>
        <mesh filename="file:///home/tecchio/code/catkin_learnbotics/src/learnrobotics/model/stl/modified/EsferaNoCentro.stl" />
      </geometry>
      <material name="abs_green">
        <color rgba="0 1 0 1" />
      </material>
    </visual>

    <collision>
      <origin rpy="0 0 0" xyz="0 0 0" />
      <geometry>
        <mesh filename="file:///home/tecchio/code/catkin_learnbotics/src/learnrobotics/model/stl/modified/EsferaNoCentro.stl" />
      </geometry>
    </collision>

    <inertial>
      <origin rpy="0 0 0" xyz="0 0 0" />
      <mass value="0.00439458" />
      <inertia ixx="1.75495855e-07" ixy="7.17444448e-16" ixz="0" iyy="1.75495862e-07" iyz="0" izz="1.75398549e-07" />
    </inertial>
  </link>

  <joint name="chassis_to_sphere" type="continuous">
    <parent link="chassis" />
    <child link="sphere" />
    <origin rpy=" 0 0 0" xyz="0.02826274 0.00014962 -0.0646" />
    <axis xyz="0 1 0" />
  </joint>

  <gazebo reference="sphere">
    <material>Gazebo/Green</material>
  </gazebo>

  <link name="sphere_2">
    <visual>
      <origin rpy="0 0 0" xyz="0 0 0" />
      <geometry>
        <mesh filename="file:///home/tecchio/code/catkin_learnbotics/src/learnrobotics/model/stl/modified/EsferaNoCentro.stl" />
      </geometry>
      <material name="abs_green">
        <color rgba="0 1 0 1" />
      </material>
    </visual>

    <collision>
      <origin rpy="0 0 0" xyz="0 0 0" />
      <geometry>
        <mesh filename="file:///home/tecchio/code/catkin_learnbotics/src/learnrobotics/model/stl/modified/EsferaNoCentro.stl" />
      </geometry>
    </collision>

    <inertial>
      <origin rpy="0 0 0" xyz="0 0 0" />
      <mass value="1e-3" />
      <inertia ixx="1.75495855e-07" ixy="0" ixz="0" iyy="1.75495862e-07" iyz="0" izz="1.75398549e-07" />
    </inertial>
  </link>

  <joint name="sphere_to_sphere_2" type="continuous">
    <parent link="sphere" />
    <child link="sphere_2" />
    <origin rpy="0 0 0" xyz="0 0 0" />
    <axis xyz="0 0 1" />
  </joint>

  <gazebo reference="sphere_2">
    <material>Gazebo/Green</material>
  </gazebo>

  <link name="sphere_3">
    <visual>
      <origin rpy="0 0 0" xyz="0 0 0" />
      <geometry>
        <mesh filename="file:///home/tecchio/code/catkin_learnbotics/src/learnrobotics/model/stl/modified/EsferaNoCentro.stl" />
      </geometry>
      <material name="abs_green">
        <color rgba="0 1 0 1" />
      </material>
    </visual>

    <collision>
      <origin rpy="0 0 0" xyz="0 0 0" />
      <geometry>
        <mesh filename="file:///home/tecchio/code/catkin_learnbotics/src/learnrobotics/model/stl/modified/EsferaNoCentro.stl" />
      </geometry>
    </collision>

    <inertial>
      <origin rpy="0 0 0" xyz="0 0 0" />
      <mass value="1e-3" />
      <inertia ixx="1.75495855e-07" ixy="0" ixz="0" iyy="1.75495862e-07" iyz="0" izz="1.75398549e-07" />
    </inertial>
  </link>

  <joint name="sphere_2_to_sphere_3" type="continuous">
    <parent link="sphere_2" />
    <child link="sphere_3" />
    <origin rpy="0 0 0" xyz="0 0 0" />
    <axis xyz="1 0 0" />
  </joint>

  <gazebo reference="sphere_3">
    <material>Gazebo/Green</material>
  </gazebo>

  <xacro:arg name="gpu" default="true"/>
  <xacro:property name="gpu" value="$(arg gpu)" />

  <xacro:include filename="$(find velodyne_description)/urdf/VLP-16.urdf.xacro"/>
  <VLP-16 parent="chassis" name="velodyne" topic="/velodyne_points" hz="10" samples="440" gpu="${gpu}">
    <origin xyz="0 0 0.045" rpy="0 0 0" />
  </VLP-16>



  <link name="camera">

    <visual>
      <origin rpy="0 0 0" xyz="0 0 0"/>
      <geometry>
        <mesh filename="file:///home/tecchio/code/catkin_learnbotics/src/learnrobotics/model/stl/Camera.stl"/>
      </geometry>
    </visual>

    <collision>
      <origin rpy="0 0 0" xyz="0 0 0"/>
      <geometry>
        <mesh filename="file:///home/tecchio/code/catkin_learnbotics/src/learnrobotics/model/stl/Camera.stl"/>
      </geometry>
    </collision>

    <inertial>
      <origin rpy="0 0 0" xyz="0 0 0"/>
      <mass value="0.02"/>
      <inertia ixx="1.397e-7" ixy="0" ixz="-2.070e-12" iyy="1.512e-7" iyz="1.844e-9" izz="7.943e-8"/>
    </inertial>
  </link>

  <joint name="chassis_to_camera" type="fixed">
    <parent link="chassis"/>
    <child link="camera"/>
    <origin rpy="0 0 0" xyz="0.07456502 0 0.03016464"/>
  </joint>

  <gazebo reference="camera">
    <sensor type="camera" name="camera_top">
      <update_rate>60.0</update_rate>
      <camera name="head">
        <horizontal_fov>1.3962634</horizontal_fov>
        <image>
          <width>1366</width>
          <height>768</height>
          <format>R8G8B8</format>
        </image>
        <clip>
          <near>0.02</near>
          <far>300</far>
        </clip>
      </camera>
      <plugin name="camera_controller" filename="libgazebo_ros_camera.so">
        <alwaysOn>true</alwaysOn>
        <updateRate>0.0</updateRate>
        <cameraName>camera_top</cameraName>
        <imageTopicName>image_raw</imageTopicName>
        <cameraInfoTopicName>camera_info</cameraInfoTopicName>
        <frameName>camera</frameName>
        <hackchassisline>0.07</hackchassisline>
        <distortionK1>0.0</distortionK1>
        <distortionK2>0.0</distortionK2>
        <distortionK3>0.0</distortionK3>
        <distortionT1>0.0</distortionT1>
        <distortionT2>0.0</distortionT2>
      </plugin>
    </sensor>
  </gazebo>

  <gazebo>
    <plugin name="gazebo_ros_control" filename="libgazebo_ros_diff_drive.so">
      <robotNamespace>/</robotNamespace>
      <legacyModeNS>true</legacyModeNS>
      <alwaysOn>true</alwaysOn>
      <legacyMode>false</legacyMode>
      <updateRate>40</updateRate>
      <leftJoint>chassis_to_wheel_red</leftJoint>
      <rightJoint>chassis_to_wheel_blue</rightJoint>
      <!-- <wheelSeparation>0.11525328</wheelSeparation> -->
      <wheelSeparation>0.12302478</wheelSeparation>
      <wheelDiameter>0.07554844</wheelDiameter>
      <torque>20</torque>
      <commandTopic>cmd_vel</commandTopic>
      <odometryTopic>odom</odometryTopic>
      <odometryFrame>odom</odometryFrame>
      <publishWheelTF>true</publishWheelTF>
      <publishOdomTF>true</publishOdomTF>
      <publishWheelJointState>true</publishWheelJointState>
      <robotBaseFrame>base_link</robotBaseFrame>
    </plugin>
  </gazebo>


</robot>